<?xml version="1.0"?>
<robot name="simple6r">
  <link name="base_link"/>
  <link name="link1">
    <inertial>
      <origin xyz="0 0 0" rpy="0 0 0"/>
      <mass value="1.0"/>
      <inertia ixx="0.003" ixy="0.0" ixz="0.0" iyy="0.003" iyz="0.0" izz="0.001"/>
    </inertial>
    <visual>
      <origin xyz="0 0 0" rpy="0 0 0"/>
      <geometry><cylinder radius="0.03" length="0.2"/></geometry>
    </visual>
    <collision>
      <origin xyz="0 0 0" rpy="0 0 0"/>
      <geometry><cylinder radius="0.03" length="0.2"/></geometry>
    </collision>
  </link>
<link name="link2">
    <inertial>
      <origin xyz="0 0 0" rpy="0 0 0"/>
      <mass value="1.0"/>
      <inertia ixx="0.003" ixy="0.0" ixz="0.0" iyy="0.003" iyz="0.0" izz="0.001"/>
    </inertial>
    <visual>
      <origin xyz="0 0 0" rpy="0 0 0"/>
      <geometry><cylinder radius="0.03" length="0.2"/></geometry>
    </visual>
    <collision>
      <origin xyz="0 0 0" rpy="0 0 0"/>
      <geometry><cylinder radius="0.03" length="0.2"/></geometry>
    </collision>
  </link>
<link name="link3">
    <inertial>
      <origin xyz="0 0 0" rpy="0 0 0"/>
      <mass value="1.0"/>
      <inertia ixx="0.003" ixy="0.0" ixz="0.0" iyy="0.003" iyz="0.0" izz="0.001"/>
    </inertial>
    <visual>
      <origin xyz="0 0 0" rpy="0 0 0"/>
      <geometry><cylinder radius="0.03" length="0.2"/></geometry>
    </visual>
    <collision>
      <origin xyz="0 0 0" rpy="0 0 0"/>
      <geometry><cylinder radius="0.03" length="0.2"/></geometry>
    </collision>
  </link>
<link name="link4">
    <inertial>
      <origin xyz="0 0 0" rpy="0 0 0"/>
      <mass value="0.5"/>
      <inertia ixx="0.003" ixy="0.0" ixz="0.0" iyy="0.003" iyz="0.0" izz="0.001"/>
    </inertial>
    <visual>
      <origin xyz="0 0 0" rpy="0 0 0"/>
      <geometry><cylinder radius="0.03" length="0.2"/></geometry>
    </visual>
    <collision>
      <origin xyz="0 0 0" rpy="0 0 0"/>
      <geometry><cylinder radius="0.03" length="0.2"/></geometry>
    </collision>
  </link>
<link name="link5">
    <inertial>
      <origin xyz="0 0 0" rpy="0 0 0"/>
      <mass value="0.5"/>
      <inertia ixx="0.003" ixy="0.0" ixz="0.0" iyy="0.003" iyz="0.0" izz="0.001"/>
    </inertial>
    <visual>
      <origin xyz="0 0 0" rpy="0 0 0"/>
      <geometry><cylinder radius="0.03" length="0.12"/></geometry>
    </visual>
    <collision>
      <origin xyz="0 0 0" rpy="0 0 0"/>
      <geometry><cylinder radius="0.03" length="0.12"/></geometry>
    </collision>
  </link>
<link name="link6">
    <inertial>
      <origin xyz="0 0 0" rpy="0 0 0"/>
      <mass value="0.5"/>
      <inertia ixx="0.003" ixy="0.0" ixz="0.0" iyy="0.003" iyz="0.0" izz="0.001"/>
    </inertial>
    <visual>
      <origin xyz="0 0 0" rpy="0 0 0"/>
      <geometry><cylinder radius="0.03" length="0.12"/></geometry>
    </visual>
    <collision>
      <origin xyz="0 0 0" rpy="0 0 0"/>
      <geometry><cylinder radius="0.03" length="0.12"/></geometry>
    </collision>
  </link>
  <joint name="joint1" type="revolute">
    <parent link="base_link"/><child link="link1"/>
    <origin xyz="0 0 0.10" rpy="0 0 0"/><axis xyz="0 0 1"/>
    <limit lower="-3.1416" upper="3.1416" effort="150" velocity="2.5"/>
  </joint>
  <joint name="joint2" type="revolute">
    <parent link="link1"/><child link="link2"/>
    <origin xyz="0 0 0.20" rpy="0 0 0"/><axis xyz="0 1 0"/>
    <limit lower="-2.61799" upper="2.61799" effort="120" velocity="2.5"/>
  </joint>
  <joint name="joint3" type="revolute">
    <parent link="link2"/><child link="link3"/>
    <origin xyz="0 0 0.20" rpy="0 0 0"/><axis xyz="0 1 0"/>
    <limit lower="-2.61799" upper="2.61799" effort="120" velocity="2.5"/>
  </joint>
  <joint name="joint4" type="revolute">
    <parent link="link3"/><child link="link4"/>
    <origin xyz="0 0 0.20" rpy="0 0 0"/><axis xyz="1 0 0"/>
    <limit lower="-3.1416" upper="3.1416" effort="60" velocity="3.0"/>
  </joint>
  <joint name="joint5" type="revolute">
    <parent link="link4"/><child link="link5"/>
    <origin xyz="0 0 0.18" rpy="0 0 0"/><axis xyz="0 1 0"/>
    <limit lower="-3.1416" upper="3.1416" effort="60" velocity="3.0"/>
  </joint>
  <joint name="joint6" type="revolute">
    <parent link="link5"/><child link="link6"/>
    <origin xyz="0 0 0.12" rpy="0 0 0"/><axis xyz="1 0 0"/>
    <limit lower="-3.1416" upper="3.1416" effort="40" velocity="3.5"/>
  </joint>
</robot>